Workbook

Sheet Data_Package_Index
A1: REQ Code | B1: Data Package Name | C1: Data Request Detail | D1: Expected Format | E1: Decision Use
A2: REQ-01 | B2: Coordinate & Location | C2: Wellhead geographic coordinates (latitude/longitude), map datum, elevation, and location relative to lease/block boundaries. Essential for spatial mapping and field development planning. | D2: GIS shapefiles, CSV with WGS84 coordinates, scanned location maps | E2: Well spacing optimization, drilling location selection, surface facility layout, and environmental impact assessment.
A3: REQ-02 | B3: Well Master & Current Status | C3: Comprehensive well registry including well classification, current operational status (producing, shut-in, suspended, abandoned), well type (producer, injector, observation), and regulatory compliance status. | D3: Well master database export, regulatory filing records, internal well status reports | E3: Portfolio screening, reactivation candidate ranking, regulatory compliance review, and resource allocation prioritization.
A4: REQ-03 | B4: Production History Raw | C4: Time-series production data including oil rate, gas rate, water rate, cumulative production, water cut trend, GOR history, and decline curve parameters from first production to present. | D4: Monthly production reports, daily gauge readings, database extraction (ODBC), CSV time-series | E4: Reserve estimation, decline curve analysis, remaining recoverable volume calculation, and IOR/EOR screening.
A5: REQ-04 | B5: Latest Valid Well Test / Production Test | C5: Most recent validated production test results including flow rate measurements, choke settings, bottom-hole flowing pressure, productivity index (PI), and test validation comments. | D5: Well test reports (PDF), production test database records, Nodal analysis files | E5: Current productivity assessment, well performance benchmarking, artificial lift sizing, and workover candidate selection.
A6: REQ-05 | B6: Pressure Surveillance: SFL / WFL / BHP + Pressure Log | C6: Pressure monitoring data including Static Fluid Level (SFL), Working Fluid Level (WFL), Bottom-Hole Pressure (BHP) surveys, pressure buildup/falloff tests, and long-term reservoir pressure trends. | D6: Pressure survey reports, DST data, PBU/PFO analysis files, database trend exports | E6: Reservoir pressure maintenance evaluation, aquifer support assessment, injection efficiency analysis, and compartmentalization detection.
A7: REQ-06 | B7: Well Schematic / Completion | C7: Wellbore schematic showing casing program, completion design, tubing specifications, packer depths, landing nipples, safety valves, and subsurface equipment configuration. | D7: Well schematic diagrams (PDF/DWG), completion reports, tubing tally sheets, WellView files | E7: Workover planning, recompletion design, tubing-conveyed perforation feasibility, and well integrity assessment.
A8: REQ-07 | B8: Perforation & Zone Data | C8: Detailed perforation records including perforated intervals, shot density, phasing, perforation type (tubing-conveyed vs. wireline), and associated formation zones with top/bottom depths. | D8: Perforation tables, completion reports, wireline run summaries, database records | E8: Zonal production allocation, reperforation candidate identification, water shut-off planning, and stimulation design.
A9: REQ-08 | B9: All Sands in Pay Zone | C9: Comprehensive inventory of all sandstone reservoirs in the pay zone section including sand nomenclature, depth intervals, thickness, correlation to regional markers, and stratigraphic framework. | D9: Stratigraphic charts, correlation panels, geologic cross-sections, sand inventory tables | E9: Undeveloped sand identification, bypassed pay evaluation, infill drilling targeting, and geosteering planning.
A10: REQ-09 | B10: Reservoir / Logs / Petrophysics | C10: Petrophysical analysis results including porosity, permeability, water saturation (Sw), net-to-gross (NTG), hydrocarbon saturation (Sh), fluid contacts, and log-derived reservoir quality indicators. | D10: Petrophysical evaluation reports, LAS log files, IP software outputs, saturation-height models | E10: OOIP/OGIP estimation, STOIIP calculation, reservoir characterization, and simulation model input.
A11: REQ-10 | B11: Reserve / Opportunity Size | C11: Reserve estimates (proved, probable, possible) per well/zone, remaining recoverable volumes, opportunity sizing for workovers/reactivations, and economic threshold analysis. | D11: Reserve certification reports, opportunity register, economics spreadsheets, management presentations | E11: Capital allocation, project prioritization, reserves booking, and investor reporting.
A12: REQ-11 | B12: Artificial Lift / Pump Data | C12: Artificial lift system specifications including pump type (ESP, PCP, SRP, gas lift), pump model, setting depth, motor specifications, current operating parameters, and failure history. | D12: Pump data sheets, run-life tracking records, vendor reports, SCADA trend data | E12: Lift optimization, failure prediction, run-life extension planning, and artificial lift conversion evaluation.
... A22: REQ-21 | B22: Directional Survey Data | C22: Directional survey data including measured depth (MD), inclination, azimuth, true vertical depth (TVD), northing/easting coordinates, dogleg severity, survey stations, and well trajectory information for all drilled wells. | D22: Directional survey reports, deviation survey files, well trajectory data in tabular format, and digital survey files such as Excel, CSV, LAS, or equivalent formats. | E22: Wellbore trajectory validation, accurate well positioning, structural and reservoir model calibration, geosteering review, collision avoidance assessment, and integration with seismic, geological, and reservoir engineering workflows.

Sheet Data_Availability_Matrix
A1: ZONE ROKAN — WELL-BY-WELL DATA PACKAGE AVAILABILITY MATRIX (101 Wells)
A2: Zone | B2: # | C2: Field | D2: Well Name | E2: REQ-01 | F2: REQ-02 | G2: REQ-03 | H2: REQ-04 | I2: REQ-05 | J2: REQ-06 | K2: REQ-07 | L2: REQ-08 | M2: REQ-09 | N2: REQ-10 | O2: REQ-11 | P2: REQ-12 | Q2: REQ-13 | R2: REQ-14 | S2: REQ-15 | T2: REQ-16 | U2: REQ-17 | V2: REQ-18 | W2: REQ-19 | X2: REQ-20 | Y2: REQ-21
E3: Coordinate & Location | F3: Well Master & Current Status | G3: Production History Raw | H3: Latest Valid Well Test / Production Test | I3: Pressure Surveillance: SFL / WFL / BHP + Pressure Log | J3: Well Schematic / Completion | K3: Perforation & Zone Data | L3: All Sands in Pay Zone | M3: Reservoir / Logs / Petrophysics | N3: Reserve / Opportunity Size | O3: Artificial Lift / Pump Data | P3: Integrity / Barrier / HSE | Q3: Workover / Intervention History | R3: Facilities / Access / Utilities | S3: Economics / AFE / Commercial | T3: Final Well File & Drilling Reports | U3: Mudlogging / Lithology / Hydrocarbon Shows | V3: Wireline Log LAS Data | W3: DST, Fluid & Production-Test Analysis | X3: Core / Lab / Geoscience Analysis | Y3: Directional Survey Data
A4: Zona Rokan | B4: 1 | C4: Balam Se | D4: BLSE00020 | E4: Available | F4: Missing | G4: Available | H4: Missing | I4: Missing | J4: Available | K4: Available | L4: Partial: Not Comprehensive | M4: Available | N4: Missing | O4: Missing | P4: Partial: Not Comprehensive | Q4: Missing | R4: Missing | S4: Missing | T4: Partial: Not Comprehensive | U4: Missing | V4: Available | W4: Missing | X4: Partial: Not Comprehensive | Y4: vertical
A5: Zona Rokan | B5: 2 | C5: Bangko | D5: BNKO000149 | E5: Available | F5: Missing | G5: Available | H5: Partial: Not Comprehensive | I5: Missing | J5: Available | K5: Partial: Not Comprehensive | L5: Partial: Not Comprehensive | M5: Available | N5: Missing | O5: Missing | P5: Partial: Not Comprehensive | Q5: Missing | R5: Missing | S5: Missing | T5: Available | U5: Missing | V5: Available | W5: Missing | X5: Missing | Y5: vertical
A6: Zona Rokan | B6: 3 | C6: Bangko | D6: BNKO00014 | E6: Available | F6: Missing | G6: Available | H6: Partial: Not Comprehensive | I6: Missing | J6: Available | K6: Partial: Not Comprehensive | L6: Partial: Not Comprehensive | M6: Available | N6: Missing | O6: Missing | P6: Partial: Not Comprehensive | Q6: Missing | R6: Missing | S6: Missing | T6: Available | U6: Missing | V6: Available | W6: Missing | X6: Missing | Y6: vertical
A7: Zona Rokan | B7: 4 | C7: Bekasap So | D7: BESO00002 | E7: Available | F7: Missing | G7: Available | H7: Missing | I7: Missing | J7: Available | K7: Available | L7: Partial: Not Comprehensive | M7: Available | N7: Missing | O7: Missing | P7: Missing | Q7: Missing | R7: Missing | S7: Missing | T7: Partial: Not Comprehensive | U7: Missing | V7: Available | W7: Missing | X7: Missing | Y7: vertical
A8: Zona Rokan | B8: 5 | C8: Benar | D8: BENA00010 | E8: Available | F8: Missing | G8: Available | H8: Missing | I8: Missing | J8: Available | K8: Available | L8: Partial: Not Comprehensive | M8: Available | N8: Missing | O8: Missing | P8: Partial: Not Comprehensive | Q8: Missing | R8: Missing | S8: Missing | T8: Available | U8: Missing | V8: Available | W8: Missing | X8: Missing | Y8: vertical
A9: Zona Rokan | B9: 6 | C9: Candi | D9: CAND00006D1 | E9: Available | F9: Missing | G9: Available | H9: Missing | I9: Missing | J9: Available | K9: Available | L9: Partial: Not Comprehensive | M9: Available | N9: Missing | O9: Missing | P9: Missing | Q9: Missing | R9: Missing | S9: Missing | T9: Available | U9: Missing | V9: Available | W9: Missing | X9: Missing | Y9: Available
A10: Zona Rokan | B10: 7 | C10: Duri | D10: DURI04043 | E10: Missing | F10: Missing | G10: Missing | H10: Partial: Not Comprehensive | I10: Missing | J10: Available | K10: Available | L10: Partial: Not Comprehensive | M10: Available | N10: Missing | O10: Missing | P10: Partial: Not Comprehensive | Q10: Partial: Not Comprehensive | R10: Missing | S10: Missing | T10: Available | U10: Missing | V10: Partial: Not Comprehensive | W10: Missing | X10: Missing | Y10: vertical
A11: Zona Rokan | B11: 8 | C11: Duri | D11: DURI04052 | E11: Missing | F11: Missing | G11: Missing | H11: Missing | I11: Missing | J11: Available | K11: Available | L11: Partial: Not Comprehensive | M11: Partial: Not Comprehensive | N11: Missing | O11: Missing | P11: Partial: Not Comprehensive | Q11: Partial: Not Comprehensive | R11: Missing | S11: Missing | T11: Available | U11: Missing | V11: Missing | W11: Missing | X11: Missing | Y11: vertical
A12: Zona Rokan | B12: 9 | C12: Duri | D12: DURI04055 | E12: Missing | F12: Missing | G12: Missing | H12: Missing | I12: Missing | J12: Available | K12: Available | L12: Partial: Not Comprehensive | M12: Partial: Not Comprehensive | N12: Missing | O12: Missing | P12: Partial: Not Comprehensive | Q12: Partial: Not Comprehensive | R12: Missing | S12: Missing | T12: Available | U12: Missing | V12: Missing | W12: Missing | X12: Missing | Y12: vertical
A13: Zona Rokan | B13: 10 | C13: Duri | D13: DURI04060 | E13: Missing | F13: Missing | G13: Missing | H13: Missing | I13: Missing | J13: Available | K13: Available | L13: Partial: Not Comprehensive | M13: Partial: Not Comprehensive | N13: Missing | O13: Missing | P13: Partial: Not Comprehensive | Q13: Missing | R13: Missing | S13: Missing | T13: Available | U13: Missing | V13: Missing | W13: Missing | X13: Missing | Y13: vertical
A14: Zona Rokan | B14: 11 | C14: Duri | D14: DURI04064 | E14: Available | F14: Missing | G14: Missing | H14: Missing | I14: Missing | J14: Available | K14: Available | L14: Partial: Not Comprehensive | M14: Available | N14: Missing | O14: Missing | P14: Partial: Not Comprehensive | Q14: Partial: Not Comprehensive | R14: Missing | S14: Missing | T14: Available | U14: Missing | V14: Partial: Not Comprehensive | W14: Missing | X14: Missing | Y14: vertical
A15: Zona Rokan | B15: 12 | C15: Duri | D15: DURI04072 | E15: Available | F15: Missing | G15: Missing | H15: Missing | I15: Missing | J15: Available | K15: Available | L15: Partial: Not Comprehensive | M15: Partial: Not Comprehensive | N15: Missing | O15: Missing | P15: Partial: Not Comprehensive | Q15: Partial: Not Comprehensive | R15: Missing | S15: Missing | T15: Available | U15: Missing | V15: Missing | W15: Missing | X15: Missing | Y15: vertical
... A104: Zona Rokan | B104: 101 | C104: Singa | D104: SING00001 | E104: Available | F104: Missing | G104: Available | H104: Missing | I104: Missing | J104: Available | K104: Available | L104: Partial: Not Comprehensive | M104: Available | N104: Missing | O104: Partial: Not Comprehensive | P104: Partial: Not Comprehensive | Q104: Partial: Not Comprehensive | R104: Missing | S104: Missing | T104: Available | U104: Missing | V104: Available | W104: Partial: Not Comprehensive | X104: Partial: Not Comprehensive | Y104: vertical

Sheet Dashboard
B1: ROKAN BLOCK — DATA AVAILABILITY EXECUTIVE SUMMARY
B3: Total Wells | C3: Total Fields | D3: REQ Categories | E3: Total Data Points
B4: =COUNTA(Data_Availability_Matrix!D4:D104) -> 101 | C4: {=SUMPRODUCT(1/COUNTIF(Data_Availability_Matrix!C4:C104,Data_Availability_Matrix!C4:C104))} -> 26 | D4: =20 -> 20 | E4: =COUNTA(Data_Availability_Matrix!E4:Y104) -> 2121
B6: Overall Data Availability Distribution
B7: Status | C7: Count | D7: Percentage
B8: ="Available" -> Available | C8: =COUNTIF(Data_Availability_Matrix!E4:X104,"Available") -> 492 | D8: =C8/$E$4 -> 0.23196605
B9: ="Partial: Not Comprehensive" -> Partial: Not Comprehensive | C9: =COUNTIF(Data_Availability_Matrix!E4:X104,"Partial: Not Comprehensive") -> 342 | D9: =C9/$E$4 -> 0.1612447
B10: ="Missing" -> Missing | C10: =COUNTIF(Data_Availability_Matrix!E4:X104,"Missing") -> 1186 | D10: =C10/$E$4 -> 0.5591702
B12: Per-REQ Availability Breakdown
B13: REQ Code | C13: Available | D13: Partial | E13: Missing | F13: Avail. Rate
B14: REQ-01 | C14: =COUNTIF(Data_Availability_Matrix!E4:E104,"Available") -> 69 | D14: =COUNTIF(Data_Availability_Matrix!E4:E104,"Partial: Not Comprehensive") -> 0 | E14: =COUNTIF(Data_Availability_Matrix!E4:E104,"Missing") -> 32 | F14: =IF(C14+D14+E14=0,0,C14/(C14+D14+E14)) -> 0.68316832
B15: REQ-02 | C15: =COUNTIF(Data_Availability_Matrix!F4:F104,"Available") -> 0 | D15: =COUNTIF(Data_Availability_Matrix!F4:F104,"Partial: Not Comprehensive") -> 0 | E15: =COUNTIF(Data_Availability_Matrix!F4:F104,"Missing") -> 101 | F15: =IF(C15+D15+E15=0,0,C15/(C15+D15+E15)) -> 0
B16: REQ-03 | C16: =COUNTIF(Data_Availability_Matrix!G4:G104,"Available") -> 52 | D16: =COUNTIF(Data_Availability_Matrix!G4:G104,"Partial: Not Comprehensive") -> 0 | E16: =COUNTIF(Data_Availability_Matrix!G4:G104,"Missing") -> 49 | F16: =IF(C16+D16+E16=0,0,C16/(C16+D16+E16)) -> 0.51485149
B17: REQ-04 | C17: =COUNTIF(Data_Availability_Matrix!H4:H104,"Available") -> 0 | D17: =COUNTIF(Data_Availability_Matrix!H4:H104,"Partial: Not Comprehensive") -> 11 | E17: =COUNTIF(Data_Availability_Matrix!H4:H104,"Missing") -> 90 | F17: =IF(C17+D17+E17=0,0,C17/(C17+D17+E17)) -> 0
B18: REQ-05 | C18: =COUNTIF(Data_Availability_Matrix!I4:I104,"Available") -> 0 | D18: =COUNTIF(Data_Availability_Matrix!I4:I104,"Partial: Not Comprehensive") -> 15 | E18: =COUNTIF(Data_Availability_Matrix!I4:I104,"Missing") -> 86 | F18: =IF(C18+D18+E18=0,0,C18/(C18+D18+E18)) -> 0
B19: REQ-06 | C19: =COUNTIF(Data_Availability_Matrix!J4:J104,"Available") -> 98 | D19: =COUNTIF(Data_Availability_Matrix!J4:J104,"Partial: Not Comprehensive") -> 3 | E19: =COUNTIF(Data_Availability_Matrix!J4:J104,"Missing") -> 0 | F19: =IF(C19+D19+E19=0,0,C19/(C19+D19+E19)) -> 0.97029703
B20: REQ-07 | C20: =COUNTIF(Data_Availability_Matrix!K4:K104,"Available") -> 71 | D20: =COUNTIF(Data_Availability_Matrix!K4:K104,"Partial: Not Comprehensive") -> 30 | E20: =COUNTIF(Data_Availability_Matrix!K4:K104,"Missing") -> 0 | F20: =IF(C20+D20+E20=0,0,C20/(C20+D20+E20)) -> 0.7029703
B21: REQ-08 | C21: =COUNTIF(Data_Availability_Matrix!L4:L104,"Available") -> 0 | D21: =COUNTIF(Data_Availability_Matrix!L4:L104,"Partial: Not Comprehensive") -> 86 | E21: =COUNTIF(Data_Availability_Matrix!L4:L104,"Missing") -> 15 | F21: =IF(C21+D21+E21=0,0,C21/(C21+D21+E21)) -> 0
B22: REQ-09 | C22: =COUNTIF(Data_Availability_Matrix!M4:M104,"Available") -> 60 | D22: =COUNTIF(Data_Availability_Matrix!M4:M104,"Partial: Not Comprehensive") -> 40 | E22: =COUNTIF(Data_Availability_Matrix!M4:M104,"Missing") -> 1 | F22: =IF(C22+D22+E22=0,0,C22/(C22+D22+E22)) -> 0.59405941
B23: REQ-10 | C23: =COUNTIF(Data_Availability_Matrix!N4:N104,"Available") -> 0 | D23: =COUNTIF(Data_Availability_Matrix!N4:N104,"Partial: Not Comprehensive") -> 0 | E23: =COUNTIF(Data_Availability_Matrix!N4:N104,"Missing") -> 101 | F23: =IF(C23+D23+E23=0,0,C23/(C23+D23+E23)) -> 0
B24: REQ-11 | C24: =COUNTIF(Data_Availability_Matrix!O4:O104,"Available") -> 0 | D24: =COUNTIF(Data_Availability_Matrix!O4:O104,"Partial: Not Comprehensive") -> 2 | E24: =COUNTIF(Data_Availability_Matrix!O4:O104,"Missing") -> 99 | F24: =IF(C24+D24+E24=0,0,C24/(C24+D24+E24)) -> 0
B25: REQ-12 | C25: =COUNTIF(Data_Availability_Matrix!P4:P104,"Available") -> 0 | D25: =COUNTIF(Data_Availability_Matrix!P4:P104,"Partial: Not Comprehensive") -> 88 | E25: =COUNTIF(Data_Availability_Matrix!P4:P104,"Missing") -> 13 | F25: =IF(C25+D25+E25=0,0,C25/(C25+D25+E25)) -> 0
B26: REQ-13 | C26: =COUNTIF(Data_Availability_Matrix!Q4:Q104,"Available") -> 0 | D26: =COUNTIF(Data_Availability_Matrix!Q4:Q104,"Partial: Not Comprehensive") -> 21 | E26: =COUNTIF(Data_Availability_Matrix!Q4:Q104,"Missing") -> 80 | F26: =IF(C26+D26+E26=0,0,C26/(C26+D26+E26)) -> 0
B27: REQ-14 | C27: =COUNTIF(Data_Availability_Matrix!R4:R104,"Available") -> 0 | D27: =COUNTIF(Data_Availability_Matrix!R4:R104,"Partial: Not Comprehensive") -> 0 | E27: =COUNTIF(Data_Availability_Matrix!R4:R104,"Missing") -> 101 | F27: =IF(C27+D27+E27=0,0,C27/(C27+D27+E27)) -> 0
B28: REQ-15 | C28: =COUNTIF(Data_Availability_Matrix!S4:S104,"Available") -> 0 | D28: =COUNTIF(Data_Availability_Matrix!S4:S104,"Partial: Not Comprehensive") -> 0 | E28: =COUNTIF(Data_Availability_Matrix!S4:S104,"Missing") -> 101 | F28: =IF(C28+D28+E28=0,0,C28/(C28+D28+E28)) -> 0
B29: REQ-16 | C29: =COUNTIF(Data_Availability_Matrix!T4:T104,"Available") -> 90 | D29: =COUNTIF(Data_Availability_Matrix!T4:T104,"Partial: Not Comprehensive") -> 8 | E29: =COUNTIF(Data_Availability_Matrix!T4:T104,"Missing") -> 3 | F29: =IF(C29+D29+E29=0,0,C29/(C29+D29+E29)) -> 0.89108911
B30: REQ-17 | C30: =COUNTIF(Data_Availability_Matrix!U4:U104,"Available") -> 0 | D30: =COUNTIF(Data_Availability_Matrix!U4:U104,"Partial: Not Comprehensive") -> 0 | E30: =COUNTIF(Data_Availability_Matrix!U4:U104,"Missing") -> 101 | F30: =IF(C30+D30+E30=0,0,C30/(C30+D30+E30)) -> 0
B31: REQ-18 | C31: =COUNTIF(Data_Availability_Matrix!V4:V104,"Available") -> 52 | D31: =COUNTIF(Data_Availability_Matrix!V4:V104,"Partial: Not Comprehensive") -> 20 | E31: =COUNTIF(Data_Availability_Matrix!V4:V104,"Missing") -> 29 | F31: =IF(C31+D31+E31=0,0,C31/(C31+D31+E31)) -> 0.51485149
B32: REQ-19 | C32: =COUNTIF(Data_Availability_Matrix!W4:W104,"Available") -> 0 | D32: =COUNTIF(Data_Availability_Matrix!W4:W104,"Partial: Not Comprehensive") -> 2 | E32: =COUNTIF(Data_Availability_Matrix!W4:W104,"Missing") -> 99 | F32: =IF(C32+D32+E32=0,0,C32/(C32+D32+E32)) -> 0
B33: REQ-20 | C33: =COUNTIF(Data_Availability_Matrix!X4:X104,"Available") -> 0 | D33: =COUNTIF(Data_Availability_Matrix!X4:X104,"Partial: Not Comprehensive") -> 16 | E33: =COUNTIF(Data_Availability_Matrix!X4:X104,"Missing") -> 85 | F33: =IF(C33+D33+E33=0,0,C33/(C33+D33+E33)) -> 0
B34: REQ-21 | C34: =COUNTIF(Data_Availability_Matrix!Y4:Y104,"Available") -> 22 | D34: =COUNTIF(Data_Availability_Matrix!Y4:Y104,"Partial: Not Comprehensive") -> 0 | E34: =COUNTIF(Data_Availability_Matrix!Y4:Y104,"Missing") -> 1 | F34: =IF(C34+D34+E34=0,0,C34/(C34+D34+E34)) -> 0.95652174
B36: Field-Level Availability Summary
B37: Field | C37: Well Count | D37: Available Data | E37: Total Cells | F37: Avail. Rate
B38: Duri | C38: =COUNTIF(Data_Availability_Matrix!$C$4:$C$104,"Duri") -> 42 | D38: =SUMPRODUCT((Data_Availability_Matrix!$C$4:$C$104="Duri")*(Data_Availability_Matrix!$E$4:$X$104="Available")) -> 135 | E38: =C38*20 -> 840 | F38: =IF(E38=0,0,D38/E38) -> 0.16071429
B39: Kopar | C39: =COUNTIF(Data_Availability_Matrix!$C$4:$C$104,"Kopar") -> 9 | D39: =SUMPRODUCT((Data_Availability_Matrix!$C$4:$C$104="Kopar")*(Data_Availability_Matrix!$E$4:$X$104="Available")) -> 42 | E39: =C39*20 -> 180 | F39: =IF(E39=0,0,D39/E39) -> 0.23333333
B40: Puncak | C40: =COUNTIF(Data_Availability_Matrix!$C$4:$C$104,"Puncak") -> 7 | D40: =SUMPRODUCT((Data_Availability_Matrix!$C$4:$C$104="Puncak")*(Data_Availability_Matrix!$E$4:$X$104="Available")) -> 46 | E40: =C40*20 -> 140 | F40: =IF(E40=0,0,D40/E40) -> 0.32857143
B41: Minas | C41: =COUNTIF(Data_Availability_Matrix!$C$4:$C$104,"Minas") -> 6 | D41: =SUMPRODUCT((Data_Availability_Matrix!$C$4:$C$104="Minas")*(Data_Availability_Matrix!$E$4:$X$104="Available")) -> 38 | E41: =C41*20 -> 120 | F41: =IF(E41=0,0,D41/E41) -> 0.31666667
B42: Kelok | C42: =COUNTIF(Data_Availability_Matrix!$C$4:$C$104,"Kelok") -> 4 | D42: =SUMPRODUCT((Data_Availability_Matrix!$C$4:$C$104="Kelok")*(Data_Availability_Matrix!$E$4:$X$104="Available")) -> 28 | E42: =C42*20 -> 80 | F42: =IF(E42=0,0,D42/E42) -> 0.35
B43: Pematang Bow | C43: =COUNTIF(Data_Availability_Matrix!$C$4:$C$104,"Pematang Bow") -> 4 | D43: =SUMPRODUCT((Data_Availability_Matrix!$C$4:$C$104="Pematang Bow")*(Data_Availability_Matrix!$E$4:$X$104="Available")) -> 22 | E43: =C43*20 -> 80 | F43: =IF(E43=0,0,D43/E43) -> 0.275
B44: Jorang | C44: =COUNTIF(Data_Availability_Matrix!$C$4:$C$104,"Jorang") -> 3 | D44: =SUMPRODUCT((Data_Availability_Matrix!$C$4:$C$104="Jorang")*(Data_Availability_Matrix!$E$4:$X$104="Available")) -> 21 | E44: =C44*20 -> 60 | F44: =IF(E44=0,0,D44/E44) -> 0.35
...
